Workbook

Sheet Sheet1

Sheet Summary (consolidated)
B1: HOLDINGS | E1: TITLES | H1: NOTES
A2: Electronic Collection.Electronic Collection Interface Name | B2: 45839 | C2: 46204 | D2: Change (Jul 2026 - Jul 2025) | E2: 45839 | F2: 46204 | G2: Change (Jul 2026 - Jul 2025)
A3: TOTAL | B3: =SUM(B4:B879) -> 3581796 | C3: =SUM(C4:C879) -> 3327145 | D3: =C3-B3 -> -254651 | E3: =SUM(E4:E879) -> 3240002 | F3: =SUM(F4:F879) -> 3060897 | G3: =F3-E3 -> -179105 | H3: Status
B4: =SUMIF('Summary Managed By UCD'!$A:$A,"",'Summary Managed By UCD'!B:B)+SUMIF('Summary Managed By CDL'!$A:$A,"",'Summary Managed By CDL'!B:B) -> 4064 | C4: =SUMIF('Summary Managed By UCD'!$A:$A,"",'Summary Managed By UCD'!C:C)+SUMIF('Summary Managed By CDL'!$A:$A,"",'Summary Managed By CDL'!C:C) -> 4036 | D4: =C4-B4 -> -28 | E4: =SUMIF('Summary Managed By UCD'!$A:$A,"",'Summary Managed By UCD'!E:E)+SUMIF('Summary Managed By CDL'!$A:$A,"",'Summary Managed By CDL'!E:E) -> 3942 | F4: =SUMIF('Summary Managed By UCD'!$A:$A,"",'Summary Managed By UCD'!F:F)+SUMIF('Summary Managed By CDL'!$A:$A,"",'Summary Managed By CDL'!F:F) -> 3914 | G4: =F4-E4 -> -28 | H4: =if(and(B4>0,C4=0),"Dropped", if(and(B4=0,C4>0), "New this year",if(SUM(B4:C4)=0, "Not available at this campus","Still Available"))) -> Still Available
A5: AAPG DataPages | B5: =SUMIF('Summary Managed By UCD'!$A:$A,'Summary (consolidated)'!$A5,'Summary Managed By UCD'!B:B)+SUMIF('Summary Managed By CDL'!$A:$A,'Summary (consolidated)'!$A5,'Summary Managed By CDL'!B:B) -> 10 | C5: =SUMIF('Summary Managed By UCD'!$A:$A,'Summary (consolidated)'!$A5,'Summary Managed By UCD'!C:C)+SUMIF('Summary Managed By CDL'!$A:$A,'Summary (consolidated)'!$A5,'Summary Managed By CDL'!C:C) -> 10 | D5: =C5-B5 -> 0 | E5: =SUMIF('Summary Managed By UCD'!$A:$A,'Summary (consolidated)'!$A5,'Summary Managed By UCD'!E:E)+SUMIF('Summary Managed By CDL'!$A:$A,'Summary (consolidated)'!$A5,'Summary Managed By CDL'!E:E) -> 10 | F5: =SUMIF('Summary Managed By UCD'!$A:$A,'Summary (consolidated)'!$A5,'Summary Managed By UCD'!F:F)+SUMIF('Summary Managed By CDL'!$A:$A,'Summary (consolidated)'!$A5,'Summary Managed By CDL'!F:F) -> 10 | G5: =F5-E5 -> 0 | H5: =if(and(B5>0,C5=0),"Dropped", if(and(B5=0,C5>0), "New this year",if(SUM(B5:C5)=0, "Not available at this campus","Still Available"))) -> Still Available
A6: ACM Digital Library | B6: =SUMIF('Summary Managed By UCD'!$A:$A,'Summary (consolidated)'!$A6,'Summary Managed By UCD'!B:B)+SUMIF('Summary Managed By CDL'!$A:$A,'Summary (consolidated)'!$A6,'Summary Managed By CDL'!B:B) -> 15147 | C6: =SUMIF('Summary Managed By UCD'!$A:$A,'Summary (consolidated)'!$A6,'Summary Managed By UCD'!C:C)+SUMIF('Summary Managed By CDL'!$A:$A,'Summary (consolidated)'!$A6,'Summary Managed By CDL'!C:C) -> 16016 | D6: =C6-B6 -> 869 | E6: =SUMIF('Summary Managed By UCD'!$A:$A,'Summary (consolidated)'!$A6,'Summary Managed By UCD'!E:E)+SUMIF('Summary Managed By CDL'!$A:$A,'Summary (consolidated)'!$A6,'Summary Managed By CDL'!E:E) -> 14416 | F6: =SUMIF('Summary Managed By UCD'!$A:$A,'Summary (consolidated)'!$A6,'Summary Managed By UCD'!F:F)+SUMIF('Summary Managed By CDL'!$A:$A,'Summary (consolidated)'!$A6,'Summary Managed By CDL'!F:F) -> 15274 | G6: =F6-E6 -> 858 | H6: =if(and(B6>0,C6=0),"Dropped", if(and(B6=0,C6>0), "New this year",if(SUM(B6:C6)=0, "Not available at this campus","Still Available"))) -> Still Available
A7: AIAA Aerospace Research Central | B7: =SUMIF('Summary Managed By UCD'!$A:$A,'Summary (consolidated)'!$A7,'Summary Managed By UCD'!B:B)+SUMIF('Summary Managed By CDL'!$A:$A,'Summary (consolidated)'!$A7,'Summary Managed By CDL'!B:B) -> 1223 | C7: =SUMIF('Summary Managed By UCD'!$A:$A,'Summary (consolidated)'!$A7,'Summary Managed By UCD'!C:C)+SUMIF('Summary Managed By CDL'!$A:$A,'Summary (consolidated)'!$A7,'Summary Managed By CDL'!C:C) -> 1229 | D7: =C7-B7 -> 6 | E7: =SUMIF('Summary Managed By UCD'!$A:$A,'Summary (consolidated)'!$A7,'Summary Managed By UCD'!E:E)+SUMIF('Summary Managed By CDL'!$A:$A,'Summary (consolidated)'!$A7,'Summary Managed By CDL'!E:E) -> 1150 | F7: =SUMIF('Summary Managed By UCD'!$A:$A,'Summary (consolidated)'!$A7,'Summary Managed By UCD'!F:F)+SUMIF('Summary Managed By CDL'!$A:$A,'Summary (consolidated)'!$A7,'Summary Managed By CDL'!F:F) -> 1156 | G7: =F7-E7 -> 6 | H7: =if(and(B7>0,C7=0),"Dropped", if(and(B7=0,C7>0), "New this year",if(SUM(B7:C7)=0, "Not available at this campus","Still Available"))) -> Still Available
A8: AIP Publishing | B8: =SUMIF('Summary Managed By UCD'!$A:$A,'Summary (consolidated)'!$A8,'Summary Managed By UCD'!B:B)+SUMIF('Summary Managed By CDL'!$A:$A,'Summary (consolidated)'!$A8,'Summary Managed By CDL'!B:B) -> 3351 | C8: =SUMIF('Summary Managed By UCD'!$A:$A,'Summary (consolidated)'!$A8,'Summary Managed By UCD'!C:C)+SUMIF('Summary Managed By CDL'!$A:$A,'Summary (consolidated)'!$A8,'Summary Managed By CDL'!C:C) -> 3519 | D8: =C8-B8 -> 168 | E8: =SUMIF('Summary Managed By UCD'!$A:$A,'Summary (consolidated)'!$A8,'Summary Managed By UCD'!E:E)+SUMIF('Summary Managed By CDL'!$A:$A,'Summary (consolidated)'!$A8,'Summary Managed By CDL'!E:E) -> 3340 | F8: =SUMIF('Summary Managed By UCD'!$A:$A,'Summary (consolidated)'!$A8,'Summary Managed By UCD'!F:F)+SUMIF('Summary Managed By CDL'!$A:$A,'Summary (consolidated)'!$A8,'Summary Managed By CDL'!F:F) -> 3492 | G8: =F8-E8 -> 152 | H8: =if(and(B8>0,C8=0),"Dropped", if(and(B8=0,C8>0), "New this year",if(SUM(B8:C8)=0, "Not available at this campus","Still Available"))) -> Still Available
A9: AIP Scitation | B9: =SUMIF('Summary Managed By UCD'!$A:$A,'Summary (consolidated)'!$A9,'Summary Managed By UCD'!B:B)+SUMIF('Summary Managed By CDL'!$A:$A,'Summary (consolidated)'!$A9,'Summary Managed By CDL'!B:B) -> 0 | C9: =SUMIF('Summary Managed By UCD'!$A:$A,'Summary (consolidated)'!$A9,'Summary Managed By UCD'!C:C)+SUMIF('Summary Managed By CDL'!$A:$A,'Summary (consolidated)'!$A9,'Summary Managed By CDL'!C:C) -> 0 | D9: =C9-B9 -> 0 | E9: =SUMIF('Summary Managed By UCD'!$A:$A,'Summary (consolidated)'!$A9,'Summary Managed By UCD'!E:E)+SUMIF('Summary Managed By CDL'!$A:$A,'Summary (consolidated)'!$A9,'Summary Managed By CDL'!E:E) -> 0 | F9: =SUMIF('Summary Managed By UCD'!$A:$A,'Summary (consolidated)'!$A9,'Summary Managed By UCD'!F:F)+SUMIF('Summary Managed By CDL'!$A:$A,'Summary (consolidated)'!$A9,'Summary Managed By CDL'!F:F) -> 0 | G9: =F9-E9 -> 0 | H9: =if(and(B9>0,C9=0),"Dropped", if(and(B9=0,C9>0), "New this year",if(SUM(B9:C9)=0, "Not available at this campus","Still Available"))) -> Not available at this campus
A10: AJOL | B10: =SUMIF('Summary Managed By UCD'!$A:$A,'Summary (consolidated)'!$A10,'Summary Managed By UCD'!B:B)+SUMIF('Summary Managed By CDL'!$A:$A,'Summary (consolidated)'!$A10,'Summary Managed By CDL'!B:B) -> 1 | C10: =SUMIF('Summary Managed By UCD'!$A:$A,'Summary (consolidated)'!$A10,'Summary Managed By UCD'!C:C)+SUMIF('Summary Managed By CDL'!$A:$A,'Summary (consolidated)'!$A10,'Summary Managed By CDL'!C:C) -> 1 | D10: =C10-B10 -> 0 | E10: =SUMIF('Summary Managed By UCD'!$A:$A,'Summary (consolidated)'!$A10,'Summary Managed By UCD'!E:E)+SUMIF('Summary Managed By CDL'!$A:$A,'Summary (consolidated)'!$A10,'Summary Managed By CDL'!E:E) -> 1 | F10: =SUMIF('Summary Managed By UCD'!$A:$A,'Summary (consolidated)'!$A10,'Summary Managed By UCD'!F:F)+SUMIF('Summary Managed By CDL'!$A:$A,'Summary (consolidated)'!$A10,'Summary Managed By CDL'!F:F) -> 1 | G10: =F10-E10 -> 0 | H10: =if(and(B10>0,C10=0),"Dropped", if(and(B10=0,C10>0), "New this year",if(SUM(B10:C10)=0, "Not available at this campus","Still Available"))) -> Still Available
A11: AM (Adam Matthew) | B11: =SUMIF('Summary Managed By UCD'!$A:$A,'Summary (consolidated)'!$A11,'Summary Managed By UCD'!B:B)+SUMIF('Summary Managed By CDL'!$A:$A,'Summary (consolidated)'!$A11,'Summary Managed By CDL'!B:B) -> 69861 | C11: =SUMIF('Summary Managed By UCD'!$A:$A,'Summary (consolidated)'!$A11,'Summary Managed By UCD'!C:C)+SUMIF('Summary Managed By CDL'!$A:$A,'Summary (consolidated)'!$A11,'Summary Managed By CDL'!C:C) -> 69858 | D11: =C11-B11 -> -3 | E11: =SUMIF('Summary Managed By UCD'!$A:$A,'Summary (consolidated)'!$A11,'Summary Managed By UCD'!E:E)+SUMIF('Summary Managed By CDL'!$A:$A,'Summary (consolidated)'!$A11,'Summary Managed By CDL'!E:E) -> 68725 | F11: =SUMIF('Summary Managed By UCD'!$A:$A,'Summary (consolidated)'!$A11,'Summary Managed By UCD'!F:F)+SUMIF('Summary Managed By CDL'!$A:$A,'Summary (consolidated)'!$A11,'Summary Managed By CDL'!F:F) -> 68722 | G11: =F11-E11 -> -3 | H11: =if(and(B11>0,C11=0),"Dropped", if(and(B11=0,C11>0), "New this year",if(SUM(B11:C11)=0, "Not available at this campus","Still Available"))) -> Still Available
A12: ANU Press eTEXT | B12: =SUMIF('Summary Managed By UCD'!$A:$A,'Summary (consolidated)'!$A12,'Summary Managed By UCD'!B:B)+SUMIF('Summary Managed By CDL'!$A:$A,'Summary (consolidated)'!$A12,'Summary Managed By CDL'!B:B) -> 0 | C12: =SUMIF('Summary Managed By UCD'!$A:$A,'Summary (consolidated)'!$A12,'Summary Managed By UCD'!C:C)+SUMIF('Summary Managed By CDL'!$A:$A,'Summary (consolidated)'!$A12,'Summary Managed By CDL'!C:C) -> 0 | D12: =C12-B12 -> 0 | E12: =SUMIF('Summary Managed By UCD'!$A:$A,'Summary (consolidated)'!$A12,'Summary Managed By UCD'!E:E)+SUMIF('Summary Managed By CDL'!$A:$A,'Summary (consolidated)'!$A12,'Summary Managed By CDL'!E:E) -> 0 | F12: =SUMIF('Summary Managed By UCD'!$A:$A,'Summary (consolidated)'!$A12,'Summary Managed By UCD'!F:F)+SUMIF('Summary Managed By CDL'!$A:$A,'Summary (consolidated)'!$A12,'Summary Managed By CDL'!F:F) -> 0 | G12: =F12-E12 -> 0 | H12: =if(and(B12>0,C12=0),"Dropped", if(and(B12=0,C12>0), "New this year",if(SUM(B12:C12)=0, "Not available at this campus","Still Available"))) -> Not available at this campus
A13: ARTstor | B13: =SUMIF('Summary Managed By UCD'!$A:$A,'Summary (consolidated)'!$A13,'Summary Managed By UCD'!B:B)+SUMIF('Summary Managed By CDL'!$A:$A,'Summary (consolidated)'!$A13,'Summary Managed By CDL'!B:B) -> 0 | C13: =SUMIF('Summary Managed By UCD'!$A:$A,'Summary (consolidated)'!$A13,'Summary Managed By UCD'!C:C)+SUMIF('Summary Managed By CDL'!$A:$A,'Summary (consolidated)'!$A13,'Summary Managed By CDL'!C:C) -> 0 | D13: =C13-B13 -> 0 | E13: =SUMIF('Summary Managed By UCD'!$A:$A,'Summary (consolidated)'!$A13,'Summary Managed By UCD'!E:E)+SUMIF('Summary Managed By CDL'!$A:$A,'Summary (consolidated)'!$A13,'Summary Managed By CDL'!E:E) -> 0 | F13: =SUMIF('Summary Managed By UCD'!$A:$A,'Summary (consolidated)'!$A13,'Summary Managed By UCD'!F:F)+SUMIF('Summary Managed By CDL'!$A:$A,'Summary (consolidated)'!$A13,'Summary Managed By CDL'!F:F) -> 0 | G13: =F13-E13 -> 0 | H13: =if(and(B13>0,C13=0),"Dropped", if(and(B13=0,C13>0), "New this year",if(SUM(B13:C13)=0, "Not available at this campus","Still Available"))) -> Not available at this campus
A14: ARVO Publishing | B14: =SUMIF('Summary Managed By UCD'!$A:$A,'Summary (consolidated)'!$A14,'Summary Managed By UCD'!B:B)+SUMIF('Summary Managed By CDL'!$A:$A,'Summary (consolidated)'!$A14,'Summary Managed By CDL'!B:B) -> 0 | C14: =SUMIF('Summary Managed By UCD'!$A:$A,'Summary (consolidated)'!$A14,'Summary Managed By UCD'!C:C)+SUMIF('Summary Managed By CDL'!$A:$A,'Summary (consolidated)'!$A14,'Summary Managed By CDL'!C:C) -> 0 | D14: =C14-B14 -> 0 | E14: =SUMIF('Summary Managed By UCD'!$A:$A,'Summary (consolidated)'!$A14,'Summary Managed By UCD'!E:E)+SUMIF('Summary Managed By CDL'!$A:$A,'Summary (consolidated)'!$A14,'Summary Managed By CDL'!E:E) -> 0 | F14: =SUMIF('Summary Managed By UCD'!$A:$A,'Summary (consolidated)'!$A14,'Summary Managed By UCD'!F:F)+SUMIF('Summary Managed By CDL'!$A:$A,'Summary (consolidated)'!$A14,'Summary Managed By CDL'!F:F) -> 0 | G14: =F14-E14 -> 0 | H14: =if(and(B14>0,C14=0),"Dropped", if(and(B14=0,C14>0), "New this year",if(SUM(B14:C14)=0, "Not available at this campus","Still Available"))) -> Not available at this campus
A15: ASCE Magazines | B15: =SUMIF('Summary Managed By UCD'!$A:$A,'Summary (consolidated)'!$A15,'Summary Managed By UCD'!B:B)+SUMIF('Summary Managed By CDL'!$A:$A,'Summary (consolidated)'!$A15,'Summary Managed By CDL'!B:B) -> 2 | C15: =SUMIF('Summary Managed By UCD'!$A:$A,'Summary (consolidated)'!$A15,'Summary Managed By UCD'!C:C)+SUMIF('Summary Managed By CDL'!$A:$A,'Summary (consolidated)'!$A15,'Summary Managed By CDL'!C:C) -> 2 | D15: =C15-B15 -> 0 | E15: =SUMIF('Summary Managed By UCD'!$A:$A,'Summary (consolidated)'!$A15,'Summary Managed By UCD'!E:E)+SUMIF('Summary Managed By CDL'!$A:$A,'Summary (consolidated)'!$A15,'Summary Managed By CDL'!E:E) -> 2 | F15: =SUMIF('Summary Managed By UCD'!$A:$A,'Summary (consolidated)'!$A15,'Summary Managed By UCD'!F:F)+SUMIF('Summary Managed By CDL'!$A:$A,'Summary (consolidated)'!$A15,'Summary Managed By CDL'!F:F) -> 2 | G15: =F15-E15 -> 0 | H15: =if(and(B15>0,C15=0),"Dropped", if(and(B15=0,C15>0), "New this year",if(SUM(B15:C15)=0, "Not available at this campus","Still Available"))) -> Still Available
A16: ASM International | B16: =SUMIF('Summary Managed By UCD'!$A:$A,'Summary (consolidated)'!$A16,'Summary Managed By UCD'!B:B)+SUMIF('Summary Managed By CDL'!$A:$A,'Summary (consolidated)'!$A16,'Summary Managed By CDL'!B:B) -> 0 | C16: =SUMIF('Summary Managed By UCD'!$A:$A,'Summary (consolidated)'!$A16,'Summary Managed By UCD'!C:C)+SUMIF('Summary Managed By CDL'!$A:$A,'Summary (consolidated)'!$A16,'Summary Managed By CDL'!C:C) -> 0 | D16: =C16-B16 -> 0 | E16: =SUMIF('Summary Managed By UCD'!$A:$A,'Summary (consolidated)'!$A16,'Summary Managed By UCD'!E:E)+SUMIF('Summary Managed By CDL'!$A:$A,'Summary (consolidated)'!$A16,'Summary Managed By CDL'!E:E) -> 0 | F16: =SUMIF('Summary Managed By UCD'!$A:$A,'Summary (consolidated)'!$A16,'Summary Managed By UCD'!F:F)+SUMIF('Summary Managed By CDL'!$A:$A,'Summary (consolidated)'!$A16,'Summary Managed By CDL'!F:F) -> 0 | G16: =F16-E16 -> 0 | H16: =if(and(B16>0,C16=0),"Dropped", if(and(B16=0,C16>0), "New this year",if(SUM(B16:C16)=0, "Not available at this campus","Still Available"))) -> Not available at this campus
... A656: University of New Mexico | B656: =SUMIF('Summary Managed By UCD'!$A:$A,'Summary (consolidated)'!$A656,'Summary Managed By UCD'!B:B)+SUMIF('Summary Managed By CDL'!$A:$A,'Summary (consolidated)'!$A656,'Summary Managed By CDL'!B:B) -> 0 | C656: =SUMIF('Summary Managed By UCD'!$A:$A,'Summary (consolidated)'!$A656,'Summary Managed By UCD'!C:C)+SUMIF('Summary Managed By CDL'!$A:$A,'Summary (consolidated)'!$A656,'Summary Managed By CDL'!C:C) -> 4 | D656: =C656-B656 -> 4 | E656: =SUMIF('Summary Managed By UCD'!$A:$A,'Summary (consolidated)'!$A656,'Summary Managed By UCD'!E:E)+SUMIF('Summary Managed By CDL'!$A:$A,'Summary (consolidated)'!$A656,'Summary Managed By CDL'!E:E) -> 0 | F656: =SUMIF('Summary Managed By UCD'!$A:$A,'Summary (consolidated)'!$A656,'Summary Managed By UCD'!F:F)+SUMIF('Summary Managed By CDL'!$A:$A,'Summary (consolidated)'!$A656,'Summary Managed By CDL'!F:F) -> 4 | G656: =F656-E656 -> 4 | H656: =if(and(B656>0,C656=0),"Dropped", if(and(B656=0,C656>0), "New this year",if(SUM(B656:C656)=0, "Not available at this campus","Still Available"))) -> New this year

Sheet Summary Managed By CDL
B1: HOLDINGS | E1: TITLES | H1: NOTES
A2: Electronic Collection.Electronic Collection Interface Name | B2: 45839 | C2: 46204 | D2: Change (Jul 2026 - Jul 2025) | E2: 45839 | F2: 46204 | G2: Change (Jul 2026 - Jul 2025) | I2: Notes and explanations from CDL
A3: TOTAL | B3: =SUM(B4:B879) -> 2189609 | C3: =SUM(C4:C879) -> 1987502 | D3: =C3-B3 -> -202107 | E3: =SUM(E4:E879) -> 1970970 | F3: =SUM(F4:F879) -> 1854523 | G3: =F3-E3 -> -116447 | H3: Status
B4: =SUMIF('UCD Breakdown 250701'!$A$104:$A$746,"",'UCD Breakdown 250701'!$AL$104:$AL$746)+SUMIF('UCD Breakdown 250701'!$A$104:$A$746,"",'UCD Breakdown 250701'!$AM$104:$AM$746)+SUMIF('UCD Breakdown 250701'!$A$104:$A$746,"",'UCD Breakdown 250701'!$AN$104:$AN$746)+SUMIF('UCD Breakdown 250701'!$A$104:$A$746,"",'UCD Breakdown 250701'!$AO$104:$AO$746) -> 3 | C4: =SUMIF('UCD Breakdown 260701'!$A$9:$A$323, "", 'UCD Breakdown 260701'!$C$9:$C$323) -> 1 | D4: =C4-B4 -> -2 | E4: =SUMIF('UCD Breakdown 250701'!$A$827:$A$1469,"",'UCD Breakdown 250701'!$AL$827:$AL$1469)+SUMIF('UCD Breakdown 250701'!$A$827:$A$1469,"",'UCD Breakdown 250701'!$AM$827:$AM$1469)+SUMIF('UCD Breakdown 250701'!$A$827:$A$1469,"",'UCD Breakdown 250701'!$AN$827:$AN$1469)+SUMIF('UCD Breakdown 250701'!$A$827:$A$1469,"",'UCD Breakdown 250701'!$AO$827:$AO$1469) -> 3 | F4: =SUMIF('UCD Breakdown 260701'!$A$334:$A$648, "",'UCD Breakdown 260701'!$C$334:$C$648) -> 1 | G4: =F4-E4 -> -2 | H4: =if(and(B4>0,C4=0),"Dropped", if(and(B4=0,C4>0), "New this year",if(SUM(B4:C4)=0, "Not managed for this campus by CDL","Still Available"))) -> Still Available
A5: AAPG DataPages | B5: =SUMIF('UCD Breakdown 250701'!$A$104:$A$746,'Summary Managed By CDL'!$A5,'UCD Breakdown 250701'!$AL$104:$AL$746)+SUMIF('UCD Breakdown 250701'!$A$104:$A$746,'Summary Managed By CDL'!$A5,'UCD Breakdown 250701'!$AM$104:$AM$746)+SUMIF('UCD Breakdown 250701'!$A$104:$A$746,'Summary Managed By CDL'!$A5,'UCD Breakdown 250701'!$AN$104:$AN$746)+SUMIF('UCD Breakdown 250701'!$A$104:$A$746,'Summary Managed By CDL'!$A5,'UCD Breakdown 250701'!$AO$104:$AO$746) -> 0 | C5: =SUMIF('UCD Breakdown 260701'!$A$9:$A$323, $A5, 'UCD Breakdown 260701'!$C$9:$C$323) -> 0 | D5: =C5-B5 -> 0 | E5: =SUMIF('UCD Breakdown 250701'!$A$827:$A$1469,'Summary Managed By CDL'!$A5,'UCD Breakdown 250701'!$AL$827:$AL$1469)+SUMIF('UCD Breakdown 250701'!$A$827:$A$1469,'Summary Managed By CDL'!$A5,'UCD Breakdown 250701'!$AM$827:$AM$1469)+SUMIF('UCD Breakdown 250701'!$A$827:$A$1469,'Summary Managed By CDL'!$A5,'UCD Breakdown 250701'!$AN$827:$AN$1469)+SUMIF('UCD Breakdown 250701'!$A$827:$A$1469,'Summary Managed By CDL'!$A5,'UCD Breakdown 250701'!$AO$827:$AO$1469) -> 0 | F5: =SUMIF('UCD Breakdown 260701'!$A$334:$A$648, $A5,'UCD Breakdown 260701'!$C$334:$C$648) -> 0 | G5: =F5-E5 -> 0 | H5: =if(and(B5>0,C5=0),"Dropped", if(and(B5=0,C5>0), "New this year",if(SUM(B5:C5)=0, "Not managed for this campus by CDL","Still Available"))) -> Not managed for this campus by CDL
A6: ACM Digital Library | B6: =SUMIF('UCD Breakdown 250701'!$A$104:$A$746,'Summary Managed By CDL'!$A6,'UCD Breakdown 250701'!$AL$104:$AL$746)+SUMIF('UCD Breakdown 250701'!$A$104:$A$746,'Summary Managed By CDL'!$A6,'UCD Breakdown 250701'!$AM$104:$AM$746)+SUMIF('UCD Breakdown 250701'!$A$104:$A$746,'Summary Managed By CDL'!$A6,'UCD Breakdown 250701'!$AN$104:$AN$746)+SUMIF('UCD Breakdown 250701'!$A$104:$A$746,'Summary Managed By CDL'!$A6,'UCD Breakdown 250701'!$AO$104:$AO$746) -> 15147 | C6: =SUMIF('UCD Breakdown 260701'!$A$9:$A$323, $A6, 'UCD Breakdown 260701'!$C$9:$C$323) -> 16016 | D6: =C6-B6 -> 869 | E6: =SUMIF('UCD Breakdown 250701'!$A$827:$A$1469,'Summary Managed By CDL'!$A6,'UCD Breakdown 250701'!$AL$827:$AL$1469)+SUMIF('UCD Breakdown 250701'!$A$827:$A$1469,'Summary Managed By CDL'!$A6,'UCD Breakdown 250701'!$AM$827:$AM$1469)+SUMIF('UCD Breakdown 250701'!$A$827:$A$1469,'Summary Managed By CDL'!$A6,'UCD Breakdown 250701'!$AN$827:$AN$1469)+SUMIF('UCD Breakdown 250701'!$A$827:$A$1469,'Summary Managed By CDL'!$A6,'UCD Breakdown 250701'!$AO$827:$AO$1469) -> 14416 | F6: =SUMIF('UCD Breakdown 260701'!$A$334:$A$648, $A6,'UCD Breakdown 260701'!$C$334:$C$648) -> 15274 | G6: =F6-E6 -> 858 | H6: =if(and(B6>0,C6=0),"Dropped", if(and(B6=0,C6>0), "New this year",if(SUM(B6:C6)=0, "Not managed for this campus by CDL","Still Available"))) -> Still Available
A7: AIAA Aerospace Research Central | B7: =SUMIF('UCD Breakdown 250701'!$A$104:$A$746,'Summary Managed By CDL'!$A7,'UCD Breakdown 250701'!$AL$104:$AL$746)+SUMIF('UCD Breakdown 250701'!$A$104:$A$746,'Summary Managed By CDL'!$A7,'UCD Breakdown 250701'!$AM$104:$AM$746)+SUMIF('UCD Breakdown 250701'!$A$104:$A$746,'Summary Managed By CDL'!$A7,'UCD Breakdown 250701'!$AN$104:$AN$746)+SUMIF('UCD Breakdown 250701'!$A$104:$A$746,'Summary Managed By CDL'!$A7,'UCD Breakdown 250701'!$AO$104:$AO$746) -> 0 | C7: =SUMIF('UCD Breakdown 260701'!$A$9:$A$323, $A7, 'UCD Breakdown 260701'!$C$9:$C$323) -> 0 | D7: =C7-B7 -> 0 | E7: =SUMIF('UCD Breakdown 250701'!$A$827:$A$1469,'Summary Managed By CDL'!$A7,'UCD Breakdown 250701'!$AL$827:$AL$1469)+SUMIF('UCD Breakdown 250701'!$A$827:$A$1469,'Summary Managed By CDL'!$A7,'UCD Breakdown 250701'!$AM$827:$AM$1469)+SUMIF('UCD Breakdown 250701'!$A$827:$A$1469,'Summary Managed By CDL'!$A7,'UCD Breakdown 250701'!$AN$827:$AN$1469)+SUMIF('UCD Breakdown 250701'!$A$827:$A$1469,'Summary Managed By CDL'!$A7,'UCD Breakdown 250701'!$AO$827:$AO$1469) -> 0 | F7: =SUMIF('UCD Breakdown 260701'!$A$334:$A$648, $A7,'UCD Breakdown 260701'!$C$334:$C$648) -> 0 | G7: =F7-E7 -> 0 | H7: =if(and(B7>0,C7=0),"Dropped", if(and(B7=0,C7>0), "New this year",if(SUM(B7:C7)=0, "Not managed for this campus by CDL","Still Available"))) -> Not managed for this campus by CDL
A8: AIP Publishing | B8: =SUMIF('UCD Breakdown 250701'!$A$104:$A$746,'Summary Managed By CDL'!$A8,'UCD Breakdown 250701'!$AL$104:$AL$746)+SUMIF('UCD Breakdown 250701'!$A$104:$A$746,'Summary Managed By CDL'!$A8,'UCD Breakdown 250701'!$AM$104:$AM$746)+SUMIF('UCD Breakdown 250701'!$A$104:$A$746,'Summary Managed By CDL'!$A8,'UCD Breakdown 250701'!$AN$104:$AN$746)+SUMIF('UCD Breakdown 250701'!$A$104:$A$746,'Summary Managed By CDL'!$A8,'UCD Breakdown 250701'!$AO$104:$AO$746) -> 3349 | C8: =SUMIF('UCD Breakdown 260701'!$A$9:$A$323, $A8, 'UCD Breakdown 260701'!$C$9:$C$323) -> 3517 | D8: =C8-B8 -> 168 | E8: =SUMIF('UCD Breakdown 250701'!$A$827:$A$1469,'Summary Managed By CDL'!$A8,'UCD Breakdown 250701'!$AL$827:$AL$1469)+SUMIF('UCD Breakdown 250701'!$A$827:$A$1469,'Summary Managed By CDL'!$A8,'UCD Breakdown 250701'!$AM$827:$AM$1469)+SUMIF('UCD Breakdown 250701'!$A$827:$A$1469,'Summary Managed By CDL'!$A8,'UCD Breakdown 250701'!$AN$827:$AN$1469)+SUMIF('UCD Breakdown 250701'!$A$827:$A$1469,'Summary Managed By CDL'!$A8,'UCD Breakdown 250701'!$AO$827:$AO$1469) -> 3338 | F8: =SUMIF('UCD Breakdown 260701'!$A$334:$A$648, $A8,'UCD Breakdown 260701'!$C$334:$C$648) -> 3490 | G8: =F8-E8 -> 152 | H8: =if(and(B8>0,C8=0),"Dropped", if(and(B8=0,C8>0), "New this year",if(SUM(B8:C8)=0, "Not managed for this campus by CDL","Still Available"))) -> Still Available
A9: AIP Scitation | B9: =SUMIF('UCD Breakdown 250701'!$A$104:$A$746,'Summary Managed By CDL'!$A9,'UCD Breakdown 250701'!$AL$104:$AL$746)+SUMIF('UCD Breakdown 250701'!$A$104:$A$746,'Summary Managed By CDL'!$A9,'UCD Breakdown 250701'!$AM$104:$AM$746)+SUMIF('UCD Breakdown 250701'!$A$104:$A$746,'Summary Managed By CDL'!$A9,'UCD Breakdown 250701'!$AN$104:$AN$746)+SUMIF('UCD Breakdown 250701'!$A$104:$A$746,'Summary Managed By CDL'!$A9,'UCD Breakdown 250701'!$AO$104:$AO$746) -> 0 | C9: =SUMIF('UCD Breakdown 260701'!$A$9:$A$323, $A9, 'UCD Breakdown 260701'!$C$9:$C$323) -> 0 | D9: =C9-B9 -> 0 | E9: =SUMIF('UCD Breakdown 250701'!$A$827:$A$1469,'Summary Managed By CDL'!$A9,'UCD Breakdown 250701'!$AL$827:$AL$1469)+SUMIF('UCD Breakdown 250701'!$A$827:$A$1469,'Summary Managed By CDL'!$A9,'UCD Breakdown 250701'!$AM$827:$AM$1469)+SUMIF('UCD Breakdown 250701'!$A$827:$A$1469,'Summary Managed By CDL'!$A9,'UCD Breakdown 250701'!$AN$827:$AN$1469)+SUMIF('UCD Breakdown 250701'!$A$827:$A$1469,'Summary Managed By CDL'!$A9,'UCD Breakdown 250701'!$AO$827:$AO$1469) -> 0 | F9: =SUMIF('UCD Breakdown 260701'!$A$334:$A$648, $A9,'UCD Breakdown 260701'!$C$334:$C$648) -> 0 | G9: =F9-E9 -> 0 | H9: =if(and(B9>0,C9=0),"Dropped", if(and(B9=0,C9>0), "New this year",if(SUM(B9:C9)=0, "Not managed for this campus by CDL","Still Available"))) -> Not managed for this campus by CDL
A10: AJOL | B10: =SUMIF('UCD Breakdown 250701'!$A$104:$A$746,'Summary Managed By CDL'!$A10,'UCD Breakdown 250701'!$AL$104:$AL$746)+SUMIF('UCD Breakdown 250701'!$A$104:$A$746,'Summary Managed By CDL'!$A10,'UCD Breakdown 250701'!$AM$104:$AM$746)+SUMIF('UCD Breakdown 250701'!$A$104:$A$746,'Summary Managed By CDL'!$A10,'UCD Breakdown 250701'!$AN$104:$AN$746)+SUMIF('UCD Breakdown 250701'!$A$104:$A$746,'Summary Managed By CDL'!$A10,'UCD Breakdown 250701'!$AO$104:$AO$746) -> 0 | C10: =SUMIF('UCD Breakdown 260701'!$A$9:$A$323, $A10, 'UCD Breakdown 260701'!$C$9:$C$323) -> 0 | D10: =C10-B10 -> 0 | E10: =SUMIF('UCD Breakdown 250701'!$A$827:$A$1469,'Summary Managed By CDL'!$A10,'UCD Breakdown 250701'!$AL$827:$AL$1469)+SUMIF('UCD Breakdown 250701'!$A$827:$A$1469,'Summary Managed By CDL'!$A10,'UCD Breakdown 250701'!$AM$827:$AM$1469)+SUMIF('UCD Breakdown 250701'!$A$827:$A$1469,'Summary Managed By CDL'!$A10,'UCD Breakdown 250701'!$AN$827:$AN$1469)+SUMIF('UCD Breakdown 250701'!$A$827:$A$1469,'Summary Managed By CDL'!$A10,'UCD Breakdown 250701'!$AO$827:$AO$1469) -> 0 | F10: =SUMIF('UCD Breakdown 260701'!$A$334:$A$648, $A10,'UCD Breakdown 260701'!$C$334:$C$648) -> 0 | G10: =F10-E10 -> 0 | H10: =if(and(B10>0,C10=0),"Dropped", if(and(B10=0,C10>0), "New this year",if(SUM(B10:C10)=0, "Not managed for this campus by CDL","Still Available"))) -> Not managed for this campus by CDL
A11: AM (Adam Matthew) | B11: =SUMIF('UCD Breakdown 250701'!$A$104:$A$746,'Summary Managed By CDL'!$A11,'UCD Breakdown 250701'!$AL$104:$AL$746)+SUMIF('UCD Breakdown 250701'!$A$104:$A$746,'Summary Managed By CDL'!$A11,'UCD Breakdown 250701'!$AM$104:$AM$746)+SUMIF('UCD Breakdown 250701'!$A$104:$A$746,'Summary Managed By CDL'!$A11,'UCD Breakdown 250701'!$AN$104:$AN$746)+SUMIF('UCD Breakdown 250701'!$A$104:$A$746,'Summary Managed By CDL'!$A11,'UCD Breakdown 250701'!$AO$104:$AO$746) -> 17174 | C11: =SUMIF('UCD Breakdown 260701'!$A$9:$A$323, $A11, 'UCD Breakdown 260701'!$C$9:$C$323) -> 17175 | D11: =C11-B11 -> 1 | E11: =SUMIF('UCD Breakdown 250701'!$A$827:$A$1469,'Summary Managed By CDL'!$A11,'UCD Breakdown 250701'!$AL$827:$AL$1469)+SUMIF('UCD Breakdown 250701'!$A$827:$A$1469,'Summary Managed By CDL'!$A11,'UCD Breakdown 250701'!$AM$827:$AM$1469)+SUMIF('UCD Breakdown 250701'!$A$827:$A$1469,'Summary Managed By CDL'!$A11,'UCD Breakdown 250701'!$AN$827:$AN$1469)+SUMIF('UCD Breakdown 250701'!$A$827:$A$1469,'Summary Managed By CDL'!$A11,'UCD Breakdown 250701'!$AO$827:$AO$1469) -> 17174 | F11: =SUMIF('UCD Breakdown 260701'!$A$334:$A$648, $A11,'UCD Breakdown 260701'!$C$334:$C$648) -> 17175 | G11: =F11-E11 -> 1 | H11: =if(and(B11>0,C11=0),"Dropped", if(and(B11=0,C11>0), "New this year",if(SUM(B11:C11)=0, "Not managed for this campus by CDL","Still Available"))) -> Still Available
A12: ANU Press eTEXT | B12: =SUMIF('UCD Breakdown 250701'!$A$104:$A$746,'Summary Managed By CDL'!$A12,'UCD Breakdown 250701'!$AL$104:$AL$746)+SUMIF('UCD Breakdown 250701'!$A$104:$A$746,'Summary Managed By CDL'!$A12,'UCD Breakdown 250701'!$AM$104:$AM$746)+SUMIF('UCD Breakdown 250701'!$A$104:$A$746,'Summary Managed By CDL'!$A12,'UCD Breakdown 250701'!$AN$104:$AN$746)+SUMIF('UCD Breakdown 250701'!$A$104:$A$746,'Summary Managed By CDL'!$A12,'UCD Breakdown 250701'!$AO$104:$AO$746) -> 0 | C12: =SUMIF('UCD Breakdown 260701'!$A$9:$A$323, $A12, 'UCD Breakdown 260701'!$C$9:$C$323) -> 0 | D12: =C12-B12 -> 0 | E12: =SUMIF('UCD Breakdown 250701'!$A$827:$A$1469,'Summary Managed By CDL'!$A12,'UCD Breakdown 250701'!$AL$827:$AL$1469)+SUMIF('UCD Breakdown 250701'!$A$827:$A$1469,'Summary Managed By CDL'!$A12,'UCD Breakdown 250701'!$AM$827:$AM$1469)+SUMIF('UCD Breakdown 250701'!$A$827:$A$1469,'Summary Managed By CDL'!$A12,'UCD Breakdown 250701'!$AN$827:$AN$1469)+SUMIF('UCD Breakdown 250701'!$A$827:$A$1469,'Summary Managed By CDL'!$A12,'UCD Breakdown 250701'!$AO$827:$AO$1469) -> 0 | F12: =SUMIF('UCD Breakdown 260701'!$A$334:$A$648, $A12,'UCD Breakdown 260701'!$C$334:$C$648) -> 0 | G12: =F12-E12 -> 0 | H12: =if(and(B12>0,C12=0),"Dropped", if(and(B12=0,C12>0), "New this year",if(SUM(B12:C12)=0, "Not managed for this campus by CDL","Still Available"))) -> Not managed for this campus by CDL
A13: ARTstor | B13: =SUMIF('UCD Breakdown 250701'!$A$104:$A$746,'Summary Managed By CDL'!$A13,'UCD Breakdown 250701'!$AL$104:$AL$746)+SUMIF('UCD Breakdown 250701'!$A$104:$A$746,'Summary Managed By CDL'!$A13,'UCD Breakdown 250701'!$AM$104:$AM$746)+SUMIF('UCD Breakdown 250701'!$A$104:$A$746,'Summary Managed By CDL'!$A13,'UCD Breakdown 250701'!$AN$104:$AN$746)+SUMIF('UCD Breakdown 250701'!$A$104:$A$746,'Summary Managed By CDL'!$A13,'UCD Breakdown 250701'!$AO$104:$AO$746) -> 0 | C13: =SUMIF('UCD Breakdown 260701'!$A$9:$A$323, $A13, 'UCD Breakdown 260701'!$C$9:$C$323) -> 0 | D13: =C13-B13 -> 0 | E13: =SUMIF('UCD Breakdown 250701'!$A$827:$A$1469,'Summary Managed By CDL'!$A13,'UCD Breakdown 250701'!$AL$827:$AL$1469)+SUMIF('UCD Breakdown 250701'!$A$827:$A$1469,'Summary Managed By CDL'!$A13,'UCD Breakdown 250701'!$AM$827:$AM$1469)+SUMIF('UCD Breakdown 250701'!$A$827:$A$1469,'Summary Managed By CDL'!$A13,'UCD Breakdown 250701'!$AN$827:$AN$1469)+SUMIF('UCD Breakdown 250701'!$A$827:$A$1469,'Summary Managed By CDL'!$A13,'UCD Breakdown 250701'!$AO$827:$AO$1469) -> 0 | F13: =SUMIF('UCD Breakdown 260701'!$A$334:$A$648, $A13,'UCD Breakdown 260701'!$C$334:$C$648) -> 0 | G13: =F13-E13 -> 0 | H13: =if(and(B13>0,C13=0),"Dropped", if(and(B13=0,C13>0), "New this year",if(SUM(B13:C13)=0, "Not managed for this campus by CDL","Still Available"))) -> Not managed for this campus by CDL
A14: ARVO Publishing | B14: =SUMIF('UCD Breakdown 250701'!$A$104:$A$746,'Summary Managed By CDL'!$A14,'UCD Breakdown 250701'!$AL$104:$AL$746)+SUMIF('UCD Breakdown 250701'!$A$104:$A$746,'Summary Managed By CDL'!$A14,'UCD Breakdown 250701'!$AM$104:$AM$746)+SUMIF('UCD Breakdown 250701'!$A$104:$A$746,'Summary Managed By CDL'!$A14,'UCD Breakdown 250701'!$AN$104:$AN$746)+SUMIF('UCD Breakdown 250701'!$A$104:$A$746,'Summary Managed By CDL'!$A14,'UCD Breakdown 250701'!$AO$104:$AO$746) -> 0 | C14: =SUMIF('UCD Breakdown 260701'!$A$9:$A$323, $A14, 'UCD Breakdown 260701'!$C$9:$C$323) -> 0 | D14: =C14-B14 -> 0 | E14: =SUMIF('UCD Breakdown 250701'!$A$827:$A$1469,'Summary Managed By CDL'!$A14,'UCD Breakdown 250701'!$AL$827:$AL$1469)+SUMIF('UCD Breakdown 250701'!$A$827:$A$1469,'Summary Managed By CDL'!$A14,'UCD Breakdown 250701'!$AM$827:$AM$1469)+SUMIF('UCD Breakdown 250701'!$A$827:$A$1469,'Summary Managed By CDL'!$A14,'UCD Breakdown 250701'!$AN$827:$AN$1469)+SUMIF('UCD Breakdown 250701'!$A$827:$A$1469,'Summary Managed By CDL'!$A14,'UCD Breakdown 250701'!$AO$827:$AO$1469) -> 0 | F14: =SUMIF('UCD Breakdown 260701'!$A$334:$A$648, $A14,'UCD Breakdown 260701'!$C$334:$C$648) -> 0 | G14: =F14-E14 -> 0 | H14: =if(and(B14>0,C14=0),"Dropped", if(and(B14=0,C14>0), "New this year",if(SUM(B14:C14)=0, "Not managed for this campus by CDL","Still Available"))) -> Not managed for this campus by CDL
A15: ASCE Magazines | B15: =SUMIF('UCD Breakdown 250701'!$A$104:$A$746,'Summary Managed By CDL'!$A15,'UCD Breakdown 250701'!$AL$104:$AL$746)+SUMIF('UCD Breakdown 250701'!$A$104:$A$746,'Summary Managed By CDL'!$A15,'UCD Breakdown 250701'!$AM$104:$AM$746)+SUMIF('UCD Breakdown 250701'!$A$104:$A$746,'Summary Managed By CDL'!$A15,'UCD Breakdown 250701'!$AN$104:$AN$746)+SUMIF('UCD Breakdown 250701'!$A$104:$A$746,'Summary Managed By CDL'!$A15,'UCD Breakdown 250701'!$AO$104:$AO$746) -> 2 | C15: =SUMIF('UCD Breakdown 260701'!$A$9:$A$323, $A15, 'UCD Breakdown 260701'!$C$9:$C$323) -> 2 | D15: =C15-B15 -> 0 | E15: =SUMIF('UCD Breakdown 250701'!$A$827:$A$1469,'Summary Managed By CDL'!$A15,'UCD Breakdown 250701'!$AL$827:$AL$1469)+SUMIF('UCD Breakdown 250701'!$A$827:$A$1469,'Summary Managed By CDL'!$A15,'UCD Breakdown 250701'!$AM$827:$AM$1469)+SUMIF('UCD Breakdown 250701'!$A$827:$A$1469,'Summary Managed By CDL'!$A15,'UCD Breakdown 250701'!$AN$827:$AN$1469)+SUMIF('UCD Breakdown 250701'!$A$827:$A$1469,'Summary Managed By CDL'!$A15,'UCD Breakdown 250701'!$AO$827:$AO$1469) -> 2 | F15: =SUMIF('UCD Breakdown 260701'!$A$334:$A$648, $A15,'UCD Breakdown 260701'!$C$334:$C$648) -> 2 | G15: =F15-E15 -> 0 | H15: =if(and(B15>0,C15=0),"Dropped", if(and(B15=0,C15>0), "New this year",if(SUM(B15:C15)=0, "Not managed for this campus by CDL","Still Available"))) -> Still Available
A16: ASM International | B16: =SUMIF('UCD Breakdown 250701'!$A$104:$A$746,'Summary Managed By CDL'!$A16,'UCD Breakdown 250701'!$AL$104:$AL$746)+SUMIF('UCD Breakdown 250701'!$A$104:$A$746,'Summary Managed By CDL'!$A16,'UCD Breakdown 250701'!$AM$104:$AM$746)+SUMIF('UCD Breakdown 250701'!$A$104:$A$746,'Summary Managed By CDL'!$A16,'UCD Breakdown 250701'!$AN$104:$AN$746)+SUMIF('UCD Breakdown 250701'!$A$104:$A$746,'Summary Managed By CDL'!$A16,'UCD Breakdown 250701'!$AO$104:$AO$746) -> 0 | C16: =SUMIF('UCD Breakdown 260701'!$A$9:$A$323, $A16, 'UCD Breakdown 260701'!$C$9:$C$323) -> 0 | D16: =C16-B16 -> 0 | E16: =SUMIF('UCD Breakdown 250701'!$A$827:$A$1469,'Summary Managed By CDL'!$A16,'UCD Breakdown 250701'!$AL$827:$AL$1469)+SUMIF('UCD Breakdown 250701'!$A$827:$A$1469,'Summary Managed By CDL'!$A16,'UCD Breakdown 250701'!$AM$827:$AM$1469)+SUMIF('UCD Breakdown 250701'!$A$827:$A$1469,'Summary Managed By CDL'!$A16,'UCD Breakdown 250701'!$AN$827:$AN$1469)+SUMIF('UCD Breakdown 250701'!$A$827:$A$1469,'Summary Managed By CDL'!$A16,'UCD Breakdown 250701'!$AO$827:$AO$1469) -> 0 | F16: =SUMIF('UCD Breakdown 260701'!$A$334:$A$648, $A16,'UCD Breakdown 260701'!$C$334:$C$648) -> 0 | G16: =F16-E16 -> 0 | H16: =if(and(B16>0,C16=0),"Dropped", if(and(B16=0,C16>0), "New this year",if(SUM(B16:C16)=0, "Not managed for this campus by CDL","Still Available"))) -> Not managed for this campus by CDL
... A656: University of New Mexico | B656: =SUMIF('UCD Breakdown 250701'!$A$104:$A$746,'Summary Managed By CDL'!$A656,'UCD Breakdown 250701'!$AL$104:$AL$746)+SUMIF('UCD Breakdown 250701'!$A$104:$A$746,'Summary Managed By CDL'!$A656,'UCD Breakdown 250701'!$AM$104:$AM$746)+SUMIF('UCD Breakdown 250701'!$A$104:$A$746,'Summary Managed By CDL'!$A656,'UCD Breakdown 250701'!$AN$104:$AN$746)+SUMIF('UCD Breakdown 250701'!$A$104:$A$746,'Summary Managed By CDL'!$A656,'UCD Breakdown 250701'!$AO$104:$AO$746) -> 0 | C656: =SUMIF('UCD Breakdown 260701'!$A$9:$A$323, $A656, 'UCD Breakdown 260701'!$C$9:$C$323) -> 4 | D656: =C656-B656 -> 4 | E656: =SUMIF('UCD Breakdown 250701'!$A$827:$A$1469,'Summary Managed By CDL'!$A656,'UCD Breakdown 250701'!$AL$827:$AL$1469)+SUMIF('UCD Breakdown 250701'!$A$827:$A$1469,'Summary Managed By CDL'!$A656,'UCD Breakdown 250701'!$AM$827:$AM$1469)+SUMIF('UCD Breakdown 250701'!$A$827:$A$1469,'Summary Managed By CDL'!$A656,'UCD Breakdown 250701'!$AN$827:$AN$1469)+SUMIF('UCD Breakdown 250701'!$A$827:$A$1469,'Summary Managed By CDL'!$A656,'UCD Breakdown 250701'!$AO$827:$AO$1469) -> 0 | F656: =SUMIF('UCD Breakdown 260701'!$A$334:$A$648, $A656,'UCD Breakdown 260701'!$C$334:$C$648) -> 4 | G656: =F656-E656 -> 4 | H656: =if(and(B656>0,C656=0),"Dropped", if(and(B656=0,C656>0), "New this year",if(SUM(B656:C656)=0, "Not managed for this campus by CDL","Still Available"))) -> New this year

Sheet Summary Managed By UCD
B1: HOLDINGS | E1: TITLES | H1: NOTES
A2: Electronic Collection.Electronic Collection Interface Name | B2: 45839 | C2: 46204 | D2: Change (Jul 2026 - Jul 2025) | E2: 45839 | F2: 46204 | G2: Change (Jul 2026 - Jul 2025)
A3: TOTAL | B3: =SUM(B4:B879) -> 1392187 | C3: =SUM(C4:C879) -> 1339643 | D3: =C3-B3 -> -52544 | E3: =SUM(E4:E879) -> 1269032 | F3: =SUM(F4:F879) -> 1206374 | G3: =F3-E3 -> -62658 | H3: Status | I3: Notes and explanations from UCD
B4: =SUMIF('UCD Breakdown 250701'!$A$104:$A$746,"",'UCD Breakdown 250701'!$O$104:$O$746)+SUMIF('UCD Breakdown 250701'!$A$104:$A$746,"",'UCD Breakdown 250701'!$P$104:$P$746)+SUMIF('UCD Breakdown 250701'!$A$104:$A$746,"",'UCD Breakdown 250701'!$Q$104:$Q$746)+SUMIF('UCD Breakdown 250701'!$A$104:$A$746,"",'UCD Breakdown 250701'!$R$104:$R$746)+SUMIF('UCD Breakdown 250701'!$A$104:$A$746,"",'UCD Breakdown 250701'!$AW$104:$AW$746)+SUMIF('UCD Breakdown 250701'!$A$104:$A$746,"",'UCD Breakdown 250701'!$AX$104:$AX$746) -> 4061 | C4: =SUMIF('UCD Breakdown 260701'!$A$9:$A$323, "",'UCD Breakdown 260701'!$F$9:$F$323) -> 4035 | D4: =C4-B4 -> -26 | E4: =SUMIF('UCD Breakdown 250701'!$A$827:$A$1469,"",'UCD Breakdown 250701'!$O$827:$O$1469)+SUMIF('UCD Breakdown 250701'!$A$827:$A$1469,"",'UCD Breakdown 250701'!$P$827:$P$1469)+SUMIF('UCD Breakdown 250701'!$A$827:$A$1469,"",'UCD Breakdown 250701'!$Q$827:$Q$1469)+SUMIF('UCD Breakdown 250701'!$A$827:$A$1469,"",'UCD Breakdown 250701'!$R$827:$R$1469)+SUMIF('UCD Breakdown 250701'!$A$827:$A$1469,"",'UCD Breakdown 250701'!$AW$827:$AW$1469)+SUMIF('UCD Breakdown 250701'!$A$827:$A$1469,"",'UCD Breakdown 250701'!$AX$827:$AX$1469) -> 3939 | F4: =sumif('UCD Breakdown 260701'!$A$334:$A$648, "",'UCD Breakdown 260701'!$F$334:$F$648) -> 3913 | G4: =F4-E4 -> -26 | H4: =if(and(B4>0,C4=0),"Dropped", if(and(B4=0,C4>0), "New this year",if(SUM(B4:C4)=0, "Not managed by this campus","Still Available"))) -> Still Available
A5: AAPG DataPages | B5: =SUMIF('UCD Breakdown 250701'!$A$104:$A$746,'Summary Managed By UCD'!$A5,'UCD Breakdown 250701'!$O$104:$O$746)+SUMIF('UCD Breakdown 250701'!$A$104:$A$746,'Summary Managed By UCD'!$A5,'UCD Breakdown 250701'!$P$104:$P$746)+SUMIF('UCD Breakdown 250701'!$A$104:$A$746,'Summary Managed By UCD'!$A5,'UCD Breakdown 250701'!$Q$104:$Q$746)+SUMIF('UCD Breakdown 250701'!$A$104:$A$746,'Summary Managed By UCD'!$A5,'UCD Breakdown 250701'!$R$104:$R$746)+SUMIF('UCD Breakdown 250701'!$A$104:$A$746,'Summary Managed By UCD'!$A5,'UCD Breakdown 250701'!$AW$104:$AW$746)+SUMIF('UCD Breakdown 250701'!$A$104:$A$746,'Summary Managed By UCD'!$A5,'UCD Breakdown 250701'!$AX$104:$AX$746) -> 10 | C5: =SUMIF('UCD Breakdown 260701'!$A$9:$A$323, $A5,'UCD Breakdown 260701'!$F$9:$F$323) -> 10 | D5: =C5-B5 -> 0 | E5: =SUMIF('UCD Breakdown 250701'!$A$827:$A$1469,'Summary Managed By UCD'!$A5,'UCD Breakdown 250701'!$O$827:$O$1469)+SUMIF('UCD Breakdown 250701'!$A$827:$A$1469,'Summary Managed By UCD'!$A5,'UCD Breakdown 250701'!$P$827:$P$1469)+SUMIF('UCD Breakdown 250701'!$A$827:$A$1469,'Summary Managed By UCD'!$A5,'UCD Breakdown 250701'!$Q$827:$Q$1469)+SUMIF('UCD Breakdown 250701'!$A$827:$A$1469,'Summary Managed By UCD'!$A5,'UCD Breakdown 250701'!$R$827:$R$1469)+SUMIF('UCD Breakdown 250701'!$A$827:$A$1469,'Summary Managed By UCD'!$A5,'UCD Breakdown 250701'!$AW$827:$AW$1469)+SUMIF('UCD Breakdown 250701'!$A$827:$A$1469,'Summary Managed By UCD'!$A5,'UCD Breakdown 250701'!$AX$827:$AX$1469) -> 10 | F5: =sumif('UCD Breakdown 260701'!$A$334:$A$648, $A5,'UCD Breakdown 260701'!$F$334:$F$648) -> 10 | G5: =F5-E5 -> 0 | H5: =if(and(B5>0,C5=0),"Dropped", if(and(B5=0,C5>0), "New this year",if(SUM(B5:C5)=0, "Not managed by this campus","Still Available"))) -> Still Available
A6: ACM Digital Library | B6: =SUMIF('UCD Breakdown 250701'!$A$104:$A$746,'Summary Managed By UCD'!$A6,'UCD Breakdown 250701'!$O$104:$O$746)+SUMIF('UCD Breakdown 250701'!$A$104:$A$746,'Summary Managed By UCD'!$A6,'UCD Breakdown 250701'!$P$104:$P$746)+SUMIF('UCD Breakdown 250701'!$A$104:$A$746,'Summary Managed By UCD'!$A6,'UCD Breakdown 250701'!$Q$104:$Q$746)+SUMIF('UCD Breakdown 250701'!$A$104:$A$746,'Summary Managed By UCD'!$A6,'UCD Breakdown 250701'!$R$104:$R$746)+SUMIF('UCD Breakdown 250701'!$A$104:$A$746,'Summary Managed By UCD'!$A6,'UCD Breakdown 250701'!$AW$104:$AW$746)+SUMIF('UCD Breakdown 250701'!$A$104:$A$746,'Summary Managed By UCD'!$A6,'UCD Breakdown 250701'!$AX$104:$AX$746) -> 0 | C6: =SUMIF('UCD Breakdown 260701'!$A$9:$A$323, $A6,'UCD Breakdown 260701'!$F$9:$F$323) -> 0 | D6: =C6-B6 -> 0 | E6: =SUMIF('UCD Breakdown 250701'!$A$827:$A$1469,'Summary Managed By UCD'!$A6,'UCD Breakdown 250701'!$O$827:$O$1469)+SUMIF('UCD Breakdown 250701'!$A$827:$A$1469,'Summary Managed By UCD'!$A6,'UCD Breakdown 250701'!$P$827:$P$1469)+SUMIF('UCD Breakdown 250701'!$A$827:$A$1469,'Summary Managed By UCD'!$A6,'UCD Breakdown 250701'!$Q$827:$Q$1469)+SUMIF('UCD Breakdown 250701'!$A$827:$A$1469,'Summary Managed By UCD'!$A6,'UCD Breakdown 250701'!$R$827:$R$1469)+SUMIF('UCD Breakdown 250701'!$A$827:$A$1469,'Summary Managed By UCD'!$A6,'UCD Breakdown 250701'!$AW$827:$AW$1469)+SUMIF('UCD Breakdown 250701'!$A$827:$A$1469,'Summary Managed By UCD'!$A6,'UCD Breakdown 250701'!$AX$827:$AX$1469) -> 0 | F6: =sumif('UCD Breakdown 260701'!$A$334:$A$648, $A6,'UCD Breakdown 260701'!$F$334:$F$648) -> 0 | G6: =F6-E6 -> 0 | H6: =if(and(B6>0,C6=0),"Dropped", if(and(B6=0,C6>0), "New this year",if(SUM(B6:C6)=0, "Not managed by this campus","Still Available"))) -> Not managed by this campus
A7: AIAA Aerospace Research Central | B7: =SUMIF('UCD Breakdown 250701'!$A$104:$A$746,'Summary Managed By UCD'!$A7,'UCD Breakdown 250701'!$O$104:$O$746)+SUMIF('UCD Breakdown 250701'!$A$104:$A$746,'Summary Managed By UCD'!$A7,'UCD Breakdown 250701'!$P$104:$P$746)+SUMIF('UCD Breakdown 250701'!$A$104:$A$746,'Summary Managed By UCD'!$A7,'UCD Breakdown 250701'!$Q$104:$Q$746)+SUMIF('UCD Breakdown 250701'!$A$104:$A$746,'Summary Managed By UCD'!$A7,'UCD Breakdown 250701'!$R$104:$R$746)+SUMIF('UCD Breakdown 250701'!$A$104:$A$746,'Summary Managed By UCD'!$A7,'UCD Breakdown 250701'!$AW$104:$AW$746)+SUMIF('UCD Breakdown 250701'!$A$104:$A$746,'Summary Managed By UCD'!$A7,'UCD Breakdown 250701'!$AX$104:$AX$746) -> 1223 | C7: =SUMIF('UCD Breakdown 260701'!$A$9:$A$323, $A7,'UCD Breakdown 260701'!$F$9:$F$323) -> 1229 | D7: =C7-B7 -> 6 | E7: =SUMIF('UCD Breakdown 250701'!$A$827:$A$1469,'Summary Managed By UCD'!$A7,'UCD Breakdown 250701'!$O$827:$O$1469)+SUMIF('UCD Breakdown 250701'!$A$827:$A$1469,'Summary Managed By UCD'!$A7,'UCD Breakdown 250701'!$P$827:$P$1469)+SUMIF('UCD Breakdown 250701'!$A$827:$A$1469,'Summary Managed By UCD'!$A7,'UCD Breakdown 250701'!$Q$827:$Q$1469)+SUMIF('UCD Breakdown 250701'!$A$827:$A$1469,'Summary Managed By UCD'!$A7,'UCD Breakdown 250701'!$R$827:$R$1469)+SUMIF('UCD Breakdown 250701'!$A$827:$A$1469,'Summary Managed By UCD'!$A7,'UCD Breakdown 250701'!$AW$827:$AW$1469)+SUMIF('UCD Breakdown 250701'!$A$827:$A$1469,'Summary Managed By UCD'!$A7,'UCD Breakdown 250701'!$AX$827:$AX$1469) -> 1150 | F7: =sumif('UCD Breakdown 260701'!$A$334:$A$648, $A7,'UCD Breakdown 260701'!$F$334:$F$648) -> 1156 | G7: =F7-E7 -> 6 | H7: =if(and(B7>0,C7=0),"Dropped", if(and(B7=0,C7>0), "New this year",if(SUM(B7:C7)=0, "Not managed by this campus","Still Available"))) -> Still Available
A8: AIP Publishing | B8: =SUMIF('UCD Breakdown 250701'!$A$104:$A$746,'Summary Managed By UCD'!$A8,'UCD Breakdown 250701'!$O$104:$O$746)+SUMIF('UCD Breakdown 250701'!$A$104:$A$746,'Summary Managed By UCD'!$A8,'UCD Breakdown 250701'!$P$104:$P$746)+SUMIF('UCD Breakdown 250701'!$A$104:$A$746,'Summary Managed By UCD'!$A8,'UCD Breakdown 250701'!$Q$104:$Q$746)+SUMIF('UCD Breakdown 250701'!$A$104:$A$746,'Summary Managed By UCD'!$A8,'UCD Breakdown 250701'!$R$104:$R$746)+SUMIF('UCD Breakdown 250701'!$A$104:$A$746,'Summary Managed By UCD'!$A8,'UCD Breakdown 250701'!$AW$104:$AW$746)+SUMIF('UCD Breakdown 250701'!$A$104:$A$746,'Summary Managed By UCD'!$A8,'UCD Breakdown 250701'!$AX$104:$AX$746) -> 2 | C8: =SUMIF('UCD Breakdown 260701'!$A$9:$A$323, $A8,'UCD Breakdown 260701'!$F$9:$F$323) -> 2 | D8: =C8-B8 -> 0 | E8: =SUMIF('UCD Breakdown 250701'!$A$827:$A$1469,'Summary Managed By UCD'!$A8,'UCD Breakdown 250701'!$O$827:$O$1469)+SUMIF('UCD Breakdown 250701'!$A$827:$A$1469,'Summary Managed By UCD'!$A8,'UCD Breakdown 250701'!$P$827:$P$1469)+SUMIF('UCD Breakdown 250701'!$A$827:$A$1469,'Summary Managed By UCD'!$A8,'UCD Breakdown 250701'!$Q$827:$Q$1469)+SUMIF('UCD Breakdown 250701'!$A$827:$A$1469,'Summary Managed By UCD'!$A8,'UCD Breakdown 250701'!$R$827:$R$1469)+SUMIF('UCD Breakdown 250701'!$A$827:$A$1469,'Summary Managed By UCD'!$A8,'UCD Breakdown 250701'!$AW$827:$AW$1469)+SUMIF('UCD Breakdown 250701'!$A$827:$A$1469,'Summary Managed By UCD'!$A8,'UCD Breakdown 250701'!$AX$827:$AX$1469) -> 2 | F8: =sumif('UCD Breakdown 260701'!$A$334:$A$648, $A8,'UCD Breakdown 260701'!$F$334:$F$648) -> 2 | G8: =F8-E8 -> 0 | H8: =if(and(B8>0,C8=0),"Dropped", if(and(B8=0,C8>0), "New this year",if(SUM(B8:C8)=0, "Not managed by this campus","Still Available"))) -> Still Available
A9: AIP Scitation | B9: =SUMIF('UCD Breakdown 250701'!$A$104:$A$746,'Summary Managed By UCD'!$A9,'UCD Breakdown 250701'!$O$104:$O$746)+SUMIF('UCD Breakdown 250701'!$A$104:$A$746,'Summary Managed By UCD'!$A9,'UCD Breakdown 250701'!$P$104:$P$746)+SUMIF('UCD Breakdown 250701'!$A$104:$A$746,'Summary Managed By UCD'!$A9,'UCD Breakdown 250701'!$Q$104:$Q$746)+SUMIF('UCD Breakdown 250701'!$A$104:$A$746,'Summary Managed By UCD'!$A9,'UCD Breakdown 250701'!$R$104:$R$746)+SUMIF('UCD Breakdown 250701'!$A$104:$A$746,'Summary Managed By UCD'!$A9,'UCD Breakdown 250701'!$AW$104:$AW$746)+SUMIF('UCD Breakdown 250701'!$A$104:$A$746,'Summary Managed By UCD'!$A9,'UCD Breakdown 250701'!$AX$104:$AX$746) -> 0 | C9: =SUMIF('UCD Breakdown 260701'!$A$9:$A$323, $A9,'UCD Breakdown 260701'!$F$9:$F$323) -> 0 | D9: =C9-B9 -> 0 | E9: =SUMIF('UCD Breakdown 250701'!$A$827:$A$1469,'Summary Managed By UCD'!$A9,'UCD Breakdown 250701'!$O$827:$O$1469)+SUMIF('UCD Breakdown 250701'!$A$827:$A$1469,'Summary Managed By UCD'!$A9,'UCD Breakdown 250701'!$P$827:$P$1469)+SUMIF('UCD Breakdown 250701'!$A$827:$A$1469,'Summary Managed By UCD'!$A9,'UCD Breakdown 250701'!$Q$827:$Q$1469)+SUMIF('UCD Breakdown 250701'!$A$827:$A$1469,'Summary Managed By UCD'!$A9,'UCD Breakdown 250701'!$R$827:$R$1469)+SUMIF('UCD Breakdown 250701'!$A$827:$A$1469,'Summary Managed By UCD'!$A9,'UCD Breakdown 250701'!$AW$827:$AW$1469)+SUMIF('UCD Breakdown 250701'!$A$827:$A$1469,'Summary Managed By UCD'!$A9,'UCD Breakdown 250701'!$AX$827:$AX$1469) -> 0 | F9: =sumif('UCD Breakdown 260701'!$A$334:$A$648, $A9,'UCD Breakdown 260701'!$F$334:$F$648) -> 0 | G9: =F9-E9 -> 0 | H9: =if(and(B9>0,C9=0),"Dropped", if(and(B9=0,C9>0), "New this year",if(SUM(B9:C9)=0, "Not managed by this campus","Still Available"))) -> Not managed by this campus
A10: AJOL | B10: =SUMIF('UCD Breakdown 250701'!$A$104:$A$746,'Summary Managed By UCD'!$A10,'UCD Breakdown 250701'!$O$104:$O$746)+SUMIF('UCD Breakdown 250701'!$A$104:$A$746,'Summary Managed By UCD'!$A10,'UCD Breakdown 250701'!$P$104:$P$746)+SUMIF('UCD Breakdown 250701'!$A$104:$A$746,'Summary Managed By UCD'!$A10,'UCD Breakdown 250701'!$Q$104:$Q$746)+SUMIF('UCD Breakdown 250701'!$A$104:$A$746,'Summary Managed By UCD'!$A10,'UCD Breakdown 250701'!$R$104:$R$746)+SUMIF('UCD Breakdown 250701'!$A$104:$A$746,'Summary Managed By UCD'!$A10,'UCD Breakdown 250701'!$AW$104:$AW$746)+SUMIF('UCD Breakdown 250701'!$A$104:$A$746,'Summary Managed By UCD'!$A10,'UCD Breakdown 250701'!$AX$104:$AX$746) -> 1 | C10: =SUMIF('UCD Breakdown 260701'!$A$9:$A$323, $A10,'UCD Breakdown 260701'!$F$9:$F$323) -> 1 | D10: =C10-B10 -> 0 | E10: =SUMIF('UCD Breakdown 250701'!$A$827:$A$1469,'Summary Managed By UCD'!$A10,'UCD Breakdown 250701'!$O$827:$O$1469)+SUMIF('UCD Breakdown 250701'!$A$827:$A$1469,'Summary Managed By UCD'!$A10,'UCD Breakdown 250701'!$P$827:$P$1469)+SUMIF('UCD Breakdown 250701'!$A$827:$A$1469,'Summary Managed By UCD'!$A10,'UCD Breakdown 250701'!$Q$827:$Q$1469)+SUMIF('UCD Breakdown 250701'!$A$827:$A$1469,'Summary Managed By UCD'!$A10,'UCD Breakdown 250701'!$R$827:$R$1469)+SUMIF('UCD Breakdown 250701'!$A$827:$A$1469,'Summary Managed By UCD'!$A10,'UCD Breakdown 250701'!$AW$827:$AW$1469)+SUMIF('UCD Breakdown 250701'!$A$827:$A$1469,'Summary Managed By UCD'!$A10,'UCD Breakdown 250701'!$AX$827:$AX$1469) -> 1 | F10: =sumif('UCD Breakdown 260701'!$A$334:$A$648, $A10,'UCD Breakdown 260701'!$F$334:$F$648) -> 1 | G10: =F10-E10 -> 0 | H10: =if(and(B10>0,C10=0),"Dropped", if(and(B10=0,C10>0), "New this year",if(SUM(B10:C10)=0, "Not managed by this campus","Still Available"))) -> Still Available
A11: AM (Adam Matthew) | B11: =SUMIF('UCD Breakdown 250701'!$A$104:$A$746,'Summary Managed By UCD'!$A11,'UCD Breakdown 250701'!$O$104:$O$746)+SUMIF('UCD Breakdown 250701'!$A$104:$A$746,'Summary Managed By UCD'!$A11,'UCD Breakdown 250701'!$P$104:$P$746)+SUMIF('UCD Breakdown 250701'!$A$104:$A$746,'Summary Managed By UCD'!$A11,'UCD Breakdown 250701'!$Q$104:$Q$746)+SUMIF('UCD Breakdown 250701'!$A$104:$A$746,'Summary Managed By UCD'!$A11,'UCD Breakdown 250701'!$R$104:$R$746)+SUMIF('UCD Breakdown 250701'!$A$104:$A$746,'Summary Managed By UCD'!$A11,'UCD Breakdown 250701'!$AW$104:$AW$746)+SUMIF('UCD Breakdown 250701'!$A$104:$A$746,'Summary Managed By UCD'!$A11,'UCD Breakdown 250701'!$AX$104:$AX$746) -> 52687 | C11: =SUMIF('UCD Breakdown 260701'!$A$9:$A$323, $A11,'UCD Breakdown 260701'!$F$9:$F$323) -> 52683 | D11: =C11-B11 -> -4 | E11: =SUMIF('UCD Breakdown 250701'!$A$827:$A$1469,'Summary Managed By UCD'!$A11,'UCD Breakdown 250701'!$O$827:$O$1469)+SUMIF('UCD Breakdown 250701'!$A$827:$A$1469,'Summary Managed By UCD'!$A11,'UCD Breakdown 250701'!$P$827:$P$1469)+SUMIF('UCD Breakdown 250701'!$A$827:$A$1469,'Summary Managed By UCD'!$A11,'UCD Breakdown 250701'!$Q$827:$Q$1469)+SUMIF('UCD Breakdown 250701'!$A$827:$A$1469,'Summary Managed By UCD'!$A11,'UCD Breakdown 250701'!$R$827:$R$1469)+SUMIF('UCD Breakdown 250701'!$A$827:$A$1469,'Summary Managed By UCD'!$A11,'UCD Breakdown 250701'!$AW$827:$AW$1469)+SUMIF('UCD Breakdown 250701'!$A$827:$A$1469,'Summary Managed By UCD'!$A11,'UCD Breakdown 250701'!$AX$827:$AX$1469) -> 51551 | F11: =sumif('UCD Breakdown 260701'!$A$334:$A$648, $A11,'UCD Breakdown 260701'!$F$334:$F$648) -> 51547 | G11: =F11-E11 -> -4 | H11: =if(and(B11>0,C11=0),"Dropped", if(and(B11=0,C11>0), "New this year",if(SUM(B11:C11)=0, "Not managed by this campus","Still Available"))) -> Still Available
A12: ANU Press eTEXT | B12: =SUMIF('UCD Breakdown 250701'!$A$104:$A$746,'Summary Managed By UCD'!$A12,'UCD Breakdown 250701'!$O$104:$O$746)+SUMIF('UCD Breakdown 250701'!$A$104:$A$746,'Summary Managed By UCD'!$A12,'UCD Breakdown 250701'!$P$104:$P$746)+SUMIF('UCD Breakdown 250701'!$A$104:$A$746,'Summary Managed By UCD'!$A12,'UCD Breakdown 250701'!$Q$104:$Q$746)+SUMIF('UCD Breakdown 250701'!$A$104:$A$746,'Summary Managed By UCD'!$A12,'UCD Breakdown 250701'!$R$104:$R$746)+SUMIF('UCD Breakdown 250701'!$A$104:$A$746,'Summary Managed By UCD'!$A12,'UCD Breakdown 250701'!$AW$104:$AW$746)+SUMIF('UCD Breakdown 250701'!$A$104:$A$746,'Summary Managed By UCD'!$A12,'UCD Breakdown 250701'!$AX$104:$AX$746) -> 0 | C12: =SUMIF('UCD Breakdown 260701'!$A$9:$A$323, $A12,'UCD Breakdown 260701'!$F$9:$F$323) -> 0 | D12: =C12-B12 -> 0 | E12: =SUMIF('UCD Breakdown 250701'!$A$827:$A$1469,'Summary Managed By UCD'!$A12,'UCD Breakdown 250701'!$O$827:$O$1469)+SUMIF('UCD Breakdown 250701'!$A$827:$A$1469,'Summary Managed By UCD'!$A12,'UCD Breakdown 250701'!$P$827:$P$1469)+SUMIF('UCD Breakdown 250701'!$A$827:$A$1469,'Summary Managed By UCD'!$A12,'UCD Breakdown 250701'!$Q$827:$Q$1469)+SUMIF('UCD Breakdown 250701'!$A$827:$A$1469,'Summary Managed By UCD'!$A12,'UCD Breakdown 250701'!$R$827:$R$1469)+SUMIF('UCD Breakdown 250701'!$A$827:$A$1469,'Summary Managed By UCD'!$A12,'UCD Breakdown 250701'!$AW$827:$AW$1469)+SUMIF('UCD Breakdown 250701'!$A$827:$A$1469,'Summary Managed By UCD'!$A12,'UCD Breakdown 250701'!$AX$827:$AX$1469) -> 0 | F12: =sumif('UCD Breakdown 260701'!$A$334:$A$648, $A12,'UCD Breakdown 260701'!$F$334:$F$648) -> 0 | G12: =F12-E12 -> 0 | H12: =if(and(B12>0,C12=0),"Dropped", if(and(B12=0,C12>0), "New this year",if(SUM(B12:C12)=0, "Not managed by this campus","Still Available"))) -> Not managed by this campus
A13: ARTstor | B13: =SUMIF('UCD Breakdown 250701'!$A$104:$A$746,'Summary Managed By UCD'!$A13,'UCD Breakdown 250701'!$O$104:$O$746)+SUMIF('UCD Breakdown 250701'!$A$104:$A$746,'Summary Managed By UCD'!$A13,'UCD Breakdown 250701'!$P$104:$P$746)+SUMIF('UCD Breakdown 250701'!$A$104:$A$746,'Summary Managed By UCD'!$A13,'UCD Breakdown 250701'!$Q$104:$Q$746)+SUMIF('UCD Breakdown 250701'!$A$104:$A$746,'Summary Managed By UCD'!$A13,'UCD Breakdown 250701'!$R$104:$R$746)+SUMIF('UCD Breakdown 250701'!$A$104:$A$746,'Summary Managed By UCD'!$A13,'UCD Breakdown 250701'!$AW$104:$AW$746)+SUMIF('UCD Breakdown 250701'!$A$104:$A$746,'Summary Managed By UCD'!$A13,'UCD Breakdown 250701'!$AX$104:$AX$746) -> 0 | C13: =SUMIF('UCD Breakdown 260701'!$A$9:$A$323, $A13,'UCD Breakdown 260701'!$F$9:$F$323) -> 0 | D13: =C13-B13 -> 0 | E13: =SUMIF('UCD Breakdown 250701'!$A$827:$A$1469,'Summary Managed By UCD'!$A13,'UCD Breakdown 250701'!$O$827:$O$1469)+SUMIF('UCD Breakdown 250701'!$A$827:$A$1469,'Summary Managed By UCD'!$A13,'UCD Breakdown 250701'!$P$827:$P$1469)+SUMIF('UCD Breakdown 250701'!$A$827:$A$1469,'Summary Managed By UCD'!$A13,'UCD Breakdown 250701'!$Q$827:$Q$1469)+SUMIF('UCD Breakdown 250701'!$A$827:$A$1469,'Summary Managed By UCD'!$A13,'UCD Breakdown 250701'!$R$827:$R$1469)+SUMIF('UCD Breakdown 250701'!$A$827:$A$1469,'Summary Managed By UCD'!$A13,'UCD Breakdown 250701'!$AW$827:$AW$1469)+SUMIF('UCD Breakdown 250701'!$A$827:$A$1469,'Summary Managed By UCD'!$A13,'UCD Breakdown 250701'!$AX$827:$AX$1469) -> 0 | F13: =sumif('UCD Breakdown 260701'!$A$334:$A$648, $A13,'UCD Breakdown 260701'!$F$334:$F$648) -> 0 | G13: =F13-E13 -> 0 | H13: =if(and(B13>0,C13=0),"Dropped", if(and(B13=0,C13>0), "New this year",if(SUM(B13:C13)=0, "Not managed by this campus","Still Available"))) -> Not managed by this campus
A14: ARVO Publishing | B14: =SUMIF('UCD Breakdown 250701'!$A$104:$A$746,'Summary Managed By UCD'!$A14,'UCD Breakdown 250701'!$O$104:$O$746)+SUMIF('UCD Breakdown 250701'!$A$104:$A$746,'Summary Managed By UCD'!$A14,'UCD Breakdown 250701'!$P$104:$P$746)+SUMIF('UCD Breakdown 250701'!$A$104:$A$746,'Summary Managed By UCD'!$A14,'UCD Breakdown 250701'!$Q$104:$Q$746)+SUMIF('UCD Breakdown 250701'!$A$104:$A$746,'Summary Managed By UCD'!$A14,'UCD Breakdown 250701'!$R$104:$R$746)+SUMIF('UCD Breakdown 250701'!$A$104:$A$746,'Summary Managed By UCD'!$A14,'UCD Breakdown 250701'!$AW$104:$AW$746)+SUMIF('UCD Breakdown 250701'!$A$104:$A$746,'Summary Managed By UCD'!$A14,'UCD Breakdown 250701'!$AX$104:$AX$746) -> 0 | C14: =SUMIF('UCD Breakdown 260701'!$A$9:$A$323, $A14,'UCD Breakdown 260701'!$F$9:$F$323) -> 0 | D14: =C14-B14 -> 0 | E14: =SUMIF('UCD Breakdown 250701'!$A$827:$A$1469,'Summary Managed By UCD'!$A14,'UCD Breakdown 250701'!$O$827:$O$1469)+SUMIF('UCD Breakdown 250701'!$A$827:$A$1469,'Summary Managed By UCD'!$A14,'UCD Breakdown 250701'!$P$827:$P$1469)+SUMIF('UCD Breakdown 250701'!$A$827:$A$1469,'Summary Managed By UCD'!$A14,'UCD Breakdown 250701'!$Q$827:$Q$1469)+SUMIF('UCD Breakdown 250701'!$A$827:$A$1469,'Summary Managed By UCD'!$A14,'UCD Breakdown 250701'!$R$827:$R$1469)+SUMIF('UCD Breakdown 250701'!$A$827:$A$1469,'Summary Managed By UCD'!$A14,'UCD Breakdown 250701'!$AW$827:$AW$1469)+SUMIF('UCD Breakdown 250701'!$A$827:$A$1469,'Summary Managed By UCD'!$A14,'UCD Breakdown 250701'!$AX$827:$AX$1469) -> 0 | F14: =sumif('UCD Breakdown 260701'!$A$334:$A$648, $A14,'UCD Breakdown 260701'!$F$334:$F$648) -> 0 | G14: =F14-E14 -> 0 | H14: =if(and(B14>0,C14=0),"Dropped", if(and(B14=0,C14>0), "New this year",if(SUM(B14:C14)=0, "Not managed by this campus","Still Available"))) -> Not managed by this campus
A15: ASCE Magazines | B15: =SUMIF('UCD Breakdown 250701'!$A$104:$A$746,'Summary Managed By UCD'!$A15,'UCD Breakdown 250701'!$O$104:$O$746)+SUMIF('UCD Breakdown 250701'!$A$104:$A$746,'Summary Managed By UCD'!$A15,'UCD Breakdown 250701'!$P$104:$P$746)+SUMIF('UCD Breakdown 250701'!$A$104:$A$746,'Summary Managed By UCD'!$A15,'UCD Breakdown 250701'!$Q$104:$Q$746)+SUMIF('UCD Breakdown 250701'!$A$104:$A$746,'Summary Managed By UCD'!$A15,'UCD Breakdown 250701'!$R$104:$R$746)+SUMIF('UCD Breakdown 250701'!$A$104:$A$746,'Summary Managed By UCD'!$A15,'UCD Breakdown 250701'!$AW$104:$AW$746)+SUMIF('UCD Breakdown 250701'!$A$104:$A$746,'Summary Managed By UCD'!$A15,'UCD Breakdown 250701'!$AX$104:$AX$746) -> 0 | C15: =SUMIF('UCD Breakdown 260701'!$A$9:$A$323, $A15,'UCD Breakdown 260701'!$F$9:$F$323) -> 0 | D15: =C15-B15 -> 0 | E15: =SUMIF('UCD Breakdown 250701'!$A$827:$A$1469,'Summary Managed By UCD'!$A15,'UCD Breakdown 250701'!$O$827:$O$1469)+SUMIF('UCD Breakdown 250701'!$A$827:$A$1469,'Summary Managed By UCD'!$A15,'UCD Breakdown 250701'!$P$827:$P$1469)+SUMIF('UCD Breakdown 250701'!$A$827:$A$1469,'Summary Managed By UCD'!$A15,'UCD Breakdown 250701'!$Q$827:$Q$1469)+SUMIF('UCD Breakdown 250701'!$A$827:$A$1469,'Summary Managed By UCD'!$A15,'UCD Breakdown 250701'!$R$827:$R$1469)+SUMIF('UCD Breakdown 250701'!$A$827:$A$1469,'Summary Managed By UCD'!$A15,'UCD Breakdown 250701'!$AW$827:$AW$1469)+SUMIF('UCD Breakdown 250701'!$A$827:$A$1469,'Summary Managed By UCD'!$A15,'UCD Breakdown 250701'!$AX$827:$AX$1469) -> 0 | F15: =sumif('UCD Breakdown 260701'!$A$334:$A$648, $A15,'UCD Breakdown 260701'!$F$334:$F$648) -> 0 | G15: =F15-E15 -> 0 | H15: =if(and(B15>0,C15=0),"Dropped", if(and(B15=0,C15>0), "New this year",if(SUM(B15:C15)=0, "Not managed by this campus","Still Available"))) -> Not managed by this campus
A16: ASM International | B16: =SUMIF('UCD Breakdown 250701'!$A$104:$A$746,'Summary Managed By UCD'!$A16,'UCD Breakdown 250701'!$O$104:$O$746)+SUMIF('UCD Breakdown 250701'!$A$104:$A$746,'Summary Managed By UCD'!$A16,'UCD Breakdown 250701'!$P$104:$P$746)+SUMIF('UCD Breakdown 250701'!$A$104:$A$746,'Summary Managed By UCD'!$A16,'UCD Breakdown 250701'!$Q$104:$Q$746)+SUMIF('UCD Breakdown 250701'!$A$104:$A$746,'Summary Managed By UCD'!$A16,'UCD Breakdown 250701'!$R$104:$R$746)+SUMIF('UCD Breakdown 250701'!$A$104:$A$746,'Summary Managed By UCD'!$A16,'UCD Breakdown 250701'!$AW$104:$AW$746)+SUMIF('UCD Breakdown 250701'!$A$104:$A$746,'Summary Managed By UCD'!$A16,'UCD Breakdown 250701'!$AX$104:$AX$746) -> 0 | C16: =SUMIF('UCD Breakdown 260701'!$A$9:$A$323, $A16,'UCD Breakdown 260701'!$F$9:$F$323) -> 0 | D16: =C16-B16 -> 0 | E16: =SUMIF('UCD Breakdown 250701'!$A$827:$A$1469,'Summary Managed By UCD'!$A16,'UCD Breakdown 250701'!$O$827:$O$1469)+SUMIF('UCD Breakdown 250701'!$A$827:$A$1469,'Summary Managed By UCD'!$A16,'UCD Breakdown 250701'!$P$827:$P$1469)+SUMIF('UCD Breakdown 250701'!$A$827:$A$1469,'Summary Managed By UCD'!$A16,'UCD Breakdown 250701'!$Q$827:$Q$1469)+SUMIF('UCD Breakdown 250701'!$A$827:$A$1469,'Summary Managed By UCD'!$A16,'UCD Breakdown 250701'!$R$827:$R$1469)+SUMIF('UCD Breakdown 250701'!$A$827:$A$1469,'Summary Managed By UCD'!$A16,'UCD Breakdown 250701'!$AW$827:$AW$1469)+SUMIF('UCD Breakdown 250701'!$A$827:$A$1469,'Summary Managed By UCD'!$A16,'UCD Breakdown 250701'!$AX$827:$AX$1469) -> 0 | F16: =sumif('UCD Breakdown 260701'!$A$334:$A$648, $A16,'UCD Breakdown 260701'!$F$334:$F$648) -> 0 | G16: =F16-E16 -> 0 | H16: =if(and(B16>0,C16=0),"Dropped", if(and(B16=0,C16>0), "New this year",if(SUM(B16:C16)=0, "Not managed by this campus","Still Available"))) -> Not managed by this campus
... A656: University of New Mexico | B656: =SUMIF('UCD Breakdown 250701'!$A$104:$A$746,'Summary Managed By UCD'!$A656,'UCD Breakdown 250701'!$O$104:$O$746)+SUMIF('UCD Breakdown 250701'!$A$104:$A$746,'Summary Managed By UCD'!$A656,'UCD Breakdown 250701'!$P$104:$P$746)+SUMIF('UCD Breakdown 250701'!$A$104:$A$746,'Summary Managed By UCD'!$A656,'UCD Breakdown 250701'!$Q$104:$Q$746)+SUMIF('UCD Breakdown 250701'!$A$104:$A$746,'Summary Managed By UCD'!$A656,'UCD Breakdown 250701'!$R$104:$R$746)+SUMIF('UCD Breakdown 250701'!$A$104:$A$746,'Summary Managed By UCD'!$A656,'UCD Breakdown 250701'!$AW$104:$AW$746)+SUMIF('UCD Breakdown 250701'!$A$104:$A$746,'Summary Managed By UCD'!$A656,'UCD Breakdown 250701'!$AX$104:$AX$746) -> 0 | C656: =SUMIF('UCD Breakdown 260701'!$A$9:$A$323, $A656,'UCD Breakdown 260701'!$F$9:$F$323) -> 0 | D656: =C656-B656 -> 0 | E656: =SUMIF('UCD Breakdown 250701'!$A$827:$A$1469,'Summary Managed By UCD'!$A656,'UCD Breakdown 250701'!$O$827:$O$1469)+SUMIF('UCD Breakdown 250701'!$A$827:$A$1469,'Summary Managed By UCD'!$A656,'UCD Breakdown 250701'!$P$827:$P$1469)+SUMIF('UCD Breakdown 250701'!$A$827:$A$1469,'Summary Managed By UCD'!$A656,'UCD Breakdown 250701'!$Q$827:$Q$1469)+SUMIF('UCD Breakdown 250701'!$A$827:$A$1469,'Summary Managed By UCD'!$A656,'UCD Breakdown 250701'!$R$827:$R$1469)+SUMIF('UCD Breakdown 250701'!$A$827:$A$1469,'Summary Managed By UCD'!$A656,'UCD Breakdown 250701'!$AW$827:$AW$1469)+SUMIF('UCD Breakdown 250701'!$A$827:$A$1469,'Summary Managed By UCD'!$A656,'UCD Breakdown 250701'!$AX$827:$AX$1469) -> 0 | F656: =sumif('UCD Breakdown 260701'!$A$334:$A$648, $A656,'UCD Breakdown 260701'!$F$334:$F$648) -> 0 | G656: =F656-E656 -> 0 | H656: =if(and(B656>0,C656=0),"Dropped", if(and(B656=0,C656>0), "New this year",if(SUM(B656:C656)=0, "Not managed by this campus","Still Available"))) -> Not managed by this campus

Sheet UCD - eResources Comparison (de
A1: UCD eResources Comparison Report
